Workbook

Sheet Details
A1: Date (DD-MM-YY) | C1: Customer | D1: PM | E1: Type | F1: Resource | H1: VPN | K1: Status | M1: Hours Spent | O1: Comments | P1: Tickets
A2: Testing | B2: Orientation | F2: Testing | G2: Orientation | H2: App/IP | I2: User | J2: Pass | K2: Testing | L2: Orientation | M2: Testing | N2: Orientation
A3: 45975 | B3: 45986 | C3: Syscom Taiwan | D3: Shobhna | E3: VPN | F3: Jabali | G3: Jabali | H3: Global Protect 60.251.169.194 | I3: exthpe_jabali_searcot_karanam | J3: YGbux#V3mrip | K3: Done | L3: Done | M3: 6 | N3: 2 | O3: Local S3 issue. Fixed | P3: 5393542826
A4: 46087 | B4: 46093 | C4: Verizon | D4: Shobhna | E4: VPN | F4: Jabali | G4: Jabali | H4: Forticlient https://63.97.174.133:10443/ 10443 | I4: asingh | J4: Xwa8xMWFcRjY3V0H | K4: Done | L4: Done | M4: 3 | N4: 2 | O4: Need to add to host file 10.77.25.22 home.rcn-pcai-ai-application.msdctf.local 10.77.25.22 *.rcn-pcai-ai-application.msdctf.local 10.77.25.22 keycloak.rcn-pcai-ai-application.msdctf.local 10.77.25.22 token-service.rcn-pcai-ai-application.msdctf.local 10.77.25.22 kubeflow.rcn-pcai-ai-application.msdctf.local 10.77.25.22 oauth2-proxy.rcn-pcai-ai-application.msdctf.local 10.77.25.22 welcome.rcn-pcai-ai-application.msdctf.local/
A5: 46093 | B5: 46186 | C5: Largan | D5: Li, Jiuxu | E5: Screen Share | F5: Jabali | G5: Jabali | H5: =IF(E5="Screen Share", "NA", "") -> NA | I5: =IF(E5="Screen Share", "NA", "") -> NA | J5: =IF(E5="Screen Share", "NA", "") -> NA | K5: Done | L5: Done | M5: 5 | N5: 2 | P5: 5401716615
C6: Tu Site Network | F6: Jabali | K6: Done
A7: 46055 | C7: Fundación Médica de Mar del Plata | D7: Shobhna | E7: Screen Share | F7: Suraj | G7: Jabali | H7: NA | I7: NA | K7: Done | M7: 3
C8: Bridgetak | F8: DJ | K8: Done | M8: 3 | N8: 2
C9: Quanser | F9: DJ | K9: Done | M9: 3 | N9: 2
C10: Unisys | F10: Ashish | K10: Done
C11: Hitachi | F11: Ashish | K11: Done
A12: 46297 | C12: Peraton | E12: Screen Share | F12: Sanjana | K12: Done | M12: 2 | N12: 1
A13: 46176 | C13: TrueMove | D13: Shobna | E13: Screen Share | F13: Sanjana | G13: DJ | K13: Done | M13: 4 | N13: 2 | O13: PCAI had URLs blocked which had to be whitelisted
C14: Dallas Cowboys | F14: Ashish | K14: Done
C15: 2 Degrees | F15: DJ | G15: DJ | K15: Done | N15: 2
A16: 46358 | C16: Court of Justice | D16: Lopamudra Dash | E16: Screen Share | F16: Suraj | H16: NA | I16: NA | K16: Done | M16: 2
A17: 46077 | C17: Kaczmarski | E17: VPN | F17: Pransshu | G17: Jabali | K17: Done | L17: Done | N17: 2
A18: 46145 | C18: HPE-GIT-2nd-G2-Large-EXP-COLO1 | D18: Aisiri/Praveen | E18: VPN | F18: Suraj | G18: DJ | H18: NA | I18: NA | K18: Done | M18: 3 | N18: 2
A19: 46056 | C19: Danfoss G2 Large | D19: Debaroon | E19: VPN | F19: Suraj | H19: u449364@danfoss.com | I19: jabali-searcot.karanam@hpe.com | J19: N@@Dar!dr@m.1123 | K19: Done | M19: 2.5
A20: 46176 | C20: Unisystem Upgrade | D20: Shobhna | E20: Screen Share | F20: Suraj | H20: NA | I20: NA | K20: Done | M20: 2
A21: 46056 | C21: Kaczmarski Upgrade | D21: Shobhna | E21: VPN | F21: Pransshu | K21: Done
A22: 46176 | C22: Sunway Digital | D22: Lopamudra Dash | E22: VPN | F22: Pransshu | G22: DJ | K22: Done
A23: 46145 | C23: HPE-GIT-G2-Large-EXP-COLO2 | D23: Aarti | E23: VPN | F23: Pransshu | G23: DJ | K23: Done | N23: 3
A24: 46329 | C24: COFORGE | D24: Praveen | E24: Screen Share | F24: Pransshu | K24: Done
A25: 46359 | B25: 46112 | C25: ZAMEK KRÓLEWSKI NA WAWELU (The Royal Castle on Wawel Hill) | D25: Hemanth | E25: Screen Share | F25: Sanjana | G25: Jabali | K25: Done | L25: Done | M25: 2 | N25: 1
A26: 46096 | C26: Sunway Digital Upgrade | D26: Lopamudra Dash | E26: VPN | F26: Pransshu | G26: Jabali | K26: Done | L26: Done | N26: 1
A27: 46097 | C27: Court of Justice Upgrade | D27: Lopamudra Dash | E27: Screen Share | F27: Pransshu | G27: DJ | K27: Done
A28: 46099 | C28: Quanser Upgrade | D28: Debaroon | E28: VPN | F28: Suraj | G28: DJ | H28: Forticlient mkvpn.quanser.com | I28: Ashukla | J28: Quan#@!@^ | K28: Done | M28: 3
A29: 46101 | C29: Peraton Upgrade | D29: Kashif | E29: Screen Share | F29: Pransshu | G29: DJ | K29: Done
A30: 46105 | B30: 46119 | C30: Columbia Lafayette | D30: Hemanth | E30: Screen Share | F30: Sanjana | G30: DJ | K30: Done | M30: 4 | N30: 2 | O30: PCAI had URLs blocked which had to be whitelisted Notebook Kernel was disconnected and Ingress pod had to be restarted
A31: 46108 | B31: 46119 | C31: Fraunhofer Gesellschaft | D31: Praveen | E31: Screen Share | F31: Suraj | G31: Jabali | H31: =IF(E31="Screen Share", "NA", "") -> NA | I31: NA | J31: =IF(E31="Screen Share", "NA", "") -> NA | K31: Done | L31: Done | M31: 1 | N31: 2
A32: 46119 | C32: COLO1-GIT-PCAIG2-LG8N-2 | D32: Aisiri | E32: VPN | F32: Suraj | G32: DJ | H32: HPE Network | K32: Done | M32: 2.5
A33: 46126 | C33: Two Degrees Mobile Limited - Upgrade | D33: Aarti | E33: VPN | F33: Suraj | H33: thirdparty.2degrees.nz | I33: nzc\Vikas.Sharma2 | J33: Vikasvishalgian$22ji | K33: Done | M33: 3 | N33: 1 | O33: Data Sources as OPA Server wasn’t Scaled Properly | P33: 5402322925
A34: 46125 | C34: TrueMove Upgrade | D34: Shobhna | E34: VPN | F34: Pransshu | G34: DJ | K34: Done
A35: 46125 | B35: 46132 | C35: Lupin Ltd | D35: Debaroon | E35: VPN | F35: Suraj | G35: Jabali | H35: https://isecure.lupin.com/Home/Login | I35: "+919901378424" | J35: Authenticator Code | K35: Done | L35: Done | M35: 2.5 | N35: 1 | O35: Slow Network, Model Deployment Consumed time
A36: 46126 | C36: Comcast | D36: Praveen | E36: Screen Share | F36: Pransshu | G36: DJ
A37: 46119 | B37: 46134 | C37: PCAI G2 CTO - L-INFRAESTRUTURAS DE PORTUGAL, S.A. | D37: Lopamudra Dash | E37: VPN | F37: Sanjana | G37: Jabali | H37: https://urldefense.com/v3/__https://vpn.infraestruturasdeportugal.pt/sslvpn/Login/Login__;!!NpxR!jweiTjtYHp71a0luU2zmAIOIiUiy3kv7n_DbXVzoqpwPZep10EQn6rsNWH1TooMX3uBrQYgbYyUdzQRBh3jXnh_eH2C2gp5Yo4M$ https://firewall.refer.pt/PortalMain | I37: s.upadhyaya.pcai@mgmt.local | J37: PRvi,78#49! | K37: Done | M37: 15 | N37: 1 | O37: 1. python https://pypi.org had to be whitelisted on production network 2. https://github.com/HPEEzmeral had to be whitelisted on production network 3. firewall rules had to be modified twice to resolve DNS related issue that was causing github to have no access on production network, thereby leading to failure to download DAGs on Airflow. 4. Kernel got disconnected leading to failures to run notebooks | P37: 5402228222
C38: Louieville | D38: Kashif | E38: Screen Share | F38: DJ | G38: DJ | M38: 6 | N38: 2
A39: 46135 | C39: SGMAI Interna Unit 2 | D39: Kashif | E39: VPN | F39: Suraj | G39: DJ | H39: mobilidade.rnsi.mai.gov.pt | I39: hpe_suraj.r-s-ext | J39: (AEG<F3z | K39: Done | M39: 2.5 | O39: Slow Network, Notebook Server spinning issue | P39: 5402495733
A40: 46132 | B40: NA | C40: ENI SPA | D40: Yousuff Shariff | E40: VPN | F40: Sanjana | G40: DJ | H40: =IF(E40="Screen Share", "NA", "") | I40: =IF(E40="Screen Share", "NA", "") | J40: =IF(E40="Screen Share", "NA", "") | K40: Done | M40: 2 | N40: 1
...

Sheet data
A1: Jabali | B1: Done | C1: VPN
A2: DJ | B2: In Progress | C2: Screen Share
A3: Suraj | B3: Blocked
A4: Pransshu | B4: Yet to Start
A5: Sanjana

Sheet Bugs
A1: Date | B1: Customer | C1: PCAI Version | D1: AIE Version | E1: Logs | F1: Solution | G1: Support Ticket
A2: 46187 | B2: QNB | C2: 1.8 | D2: 1.11 | E2: Airflow Not Up due to git sync | F2: Whitelisting in proxy and support team help in bypassing SSL self certification for github url | G2: 5403343037

Sheet Issue_Log
A1: Issue Description | B1: PCAI Version | C1: AIE Version | E1: Solution
A2: Local S3 In error state | B2: Any | C2: Any | E2: Delete and re add using the following commands kubectl get ezdatasources -n ezdata-system local-s3 -o yaml >/tmp/local-s3 kubectl delete ezdatasources -n ezdata-system local-s3 kubectl apply -f /tmp/local-s3
A3: Model issues | B3: Any | C3: Any | E3: kubectl get all -n ezai-services | grep -i llama3-8b kubectl get all -n ezai-services | grep -i reranker kubectl rollout restart deployment reranker-a1db2849-predictor-00001-deployment -n ezai-services kubectl delete configuration.serving.knative.dev/reranker-a1db2849-predictor -n ezai-services
A4: Lllama 3-70b Model Deployment issue | B4: PCAI 1.8 | C4: AIE 1.11 | E4: This is happening with RTX6K GPUs.Where we have to define the NIM_MODEL_PROFILE for the model to get deployed with the correct Profile
A5: Model deployment Failing with error specifying https://xfiles.ngc.nvidia.com | B5: PCAI 1.8 | C5: AIE 1.11 | E5: This mostly is happening because the customer hasnt whitelisted *.ngc.nvidia.com
A6: Model Deployment issue in PCAI-D Environments | B6: PCAI 1.8 | C6: AIE 1.11 | E6: all the required NIM_PROFILEs are not copied into the S3 bucket.the solution for this involves resyncing the NIM_PROFILE buckets and re running
A7: Data Sources Issues | B7: PCAI 1.8 | C7: AIE 1.12 | E7: Restart ezpresto

Sheet Stats
A1: 📊 PCAI STATISTICS DASHBOARD
A3: Current Date: | B3: =TODAY() -> 46216
A5: 📅 LAST 7 DAYS STATISTICS | D5: 👤 PER RESOURCE OVERALL STATISTICS | J5: 📅 WEEKLY STATISTICS
A6: Metric | B6: Value | D6: Resource | E6: Testing Tasks | F6: Orientation Tasks | G6: Testing Hours | H6: Orientation Hours | J6: Week Starting | K6: Testing Tasks | L6: Testing Hours | M6: Orientation Tasks | N6: Orientation Hours
A7: Total Tasks (Testing) | B7: {=SUMPRODUCT((Details!$A$3:$A$102>=TODAY()-7)*(Details!$A$3:$A$102<=TODAY())*(Details!$A$3:$A$102<>""))} -> 3 | D7: Jabali | E7: =COUNTIF(Details!$F$3:$F$102,D7) -> 4 | F7: =COUNTIF(Details!$G$3:$G$102,D7) -> 14 | G7: =SUMIF(Details!$F$3:$F$102,D7,Details!$M$3:$M$102) -> 14 | H7: =SUMIF(Details!$G$3:$G$102,D7,Details!$N$3:$N$102) -> 16 | J7: =TODAY()-WEEKDAY(TODAY(),2)+1 -> 46216 | K7: {=SUMPRODUCT((Details!$A$3:$A$102>=J7)*(Details!$A$3:$A$102<J7+7)*(Details!$A$3:$A$102<>""))} -> 0 | L7: {=SUMPRODUCT((Details!$A$3:$A$102>=J7)*(Details!$A$3:$A$102<J7+7)*1,Details!$M$3:$M$102)} -> 0 | M7: {=SUMPRODUCT((Details!$B$3:$B$102>=J7)*(Details!$B$3:$B$102<J7+7)*(Details!$B$3:$B$102<>""))} -> 1 | N7: {=SUMPRODUCT((Details!$B$3:$B$102>=J7)*(Details!$B$3:$B$102<J7+7)*1,Details!$N$3:$N$102)} -> 1 | O7: ← Current Week
A8: Total Tasks (Orientation) | B8: {=SUMPRODUCT((Details!$B$3:$B$102>=TODAY()-7)*(Details!$B$3:$B$102<=TODAY())*(Details!$B$3:$B$102<>""))} -> 3 | D8: DJ | E8: =COUNTIF(Details!$F$3:$F$102,D8) -> 5 | F8: =COUNTIF(Details!$G$3:$G$102,D8) -> 21 | G8: =SUMIF(Details!$F$3:$F$102,D8,Details!$M$3:$M$102) -> 12 | H8: =SUMIF(Details!$G$3:$G$102,D8,Details!$N$3:$N$102) -> 16.5 | J8: =J7-7 -> 46209 | K8: {=SUMPRODUCT((Details!$A$3:$A$102>=J8)*(Details!$A$3:$A$102<J8+7)*(Details!$A$3:$A$102<>""))} -> 3 | L8: {=SUMPRODUCT((Details!$A$3:$A$102>=J8)*(Details!$A$3:$A$102<J8+7)*1,Details!$M$3:$M$102)} -> 4 | M8: {=SUMPRODUCT((Details!$B$3:$B$102>=J8)*(Details!$B$3:$B$102<J8+7)*(Details!$B$3:$B$102<>""))} -> 2 | N8: {=SUMPRODUCT((Details!$B$3:$B$102>=J8)*(Details!$B$3:$B$102<J8+7)*1,Details!$N$3:$N$102)} -> 1
A9: Hours Spent (Testing) | B9: {=SUMPRODUCT((Details!$A$3:$A$102>=TODAY()-7)*(Details!$A$3:$A$102<=TODAY())*1,Details!$M$3:$M$102)} -> 4 | D9: Suraj | E9: =COUNTIF(Details!$F$3:$F$102,D9) -> 27 | F9: =COUNTIF(Details!$G$3:$G$102,D9) -> 0 | G9: =SUMIF(Details!$F$3:$F$102,D9,Details!$M$3:$M$102) -> 44 | H9: =SUMIF(Details!$G$3:$G$102,D9,Details!$N$3:$N$102) -> 0 | J9: =J8-7 -> 46202 | K9: {=SUMPRODUCT((Details!$A$3:$A$102>=J9)*(Details!$A$3:$A$102<J9+7)*(Details!$A$3:$A$102<>""))} -> 1 | L9: {=SUMPRODUCT((Details!$A$3:$A$102>=J9)*(Details!$A$3:$A$102<J9+7)*1,Details!$M$3:$M$102)} -> 1 | M9: {=SUMPRODUCT((Details!$B$3:$B$102>=J9)*(Details!$B$3:$B$102<J9+7)*(Details!$B$3:$B$102<>""))} -> 0 | N9: {=SUMPRODUCT((Details!$B$3:$B$102>=J9)*(Details!$B$3:$B$102<J9+7)*1,Details!$N$3:$N$102)} -> 0
A10: Hours Spent (Orientation) | B10: {=SUMPRODUCT((Details!$B$3:$B$102>=TODAY()-7)*(Details!$B$3:$B$102<=TODAY())*1,Details!$N$3:$N$102)} -> 2 | D10: Pransshu | E10: =COUNTIF(Details!$F$3:$F$102,D10) -> 20 | F10: =COUNTIF(Details!$G$3:$G$102,D10) -> 0 | G10: =SUMIF(Details!$F$3:$F$102,D10,Details!$M$3:$M$102) -> 3.5 | H10: =SUMIF(Details!$G$3:$G$102,D10,Details!$N$3:$N$102) -> 0 | J10: =J9-7 -> 46195 | K10: {=SUMPRODUCT((Details!$A$3:$A$102>=J10)*(Details!$A$3:$A$102<J10+7)*(Details!$A$3:$A$102<>""))} -> 7 | L10: {=SUMPRODUCT((Details!$A$3:$A$102>=J10)*(Details!$A$3:$A$102<J10+7)*1,Details!$M$3:$M$102)} -> 4.5 | M10: {=SUMPRODUCT((Details!$B$3:$B$102>=J10)*(Details!$B$3:$B$102<J10+7)*(Details!$B$3:$B$102<>""))} -> 1 | N10: {=SUMPRODUCT((Details!$B$3:$B$102>=J10)*(Details!$B$3:$B$102<J10+7)*1,Details!$N$3:$N$102)} -> 0
A11: Tasks Completed | B11: {=SUMPRODUCT((Details!$A$3:$A$102>=TODAY()-7)*(Details!$A$3:$A$102<=TODAY())*(Details!$K$3:$K$102="Done"))} -> 3 | D11: Sanjana | E11: =COUNTIF(Details!$F$3:$F$102,D11) -> 15 | F11: =COUNTIF(Details!$G$3:$G$102,D11) -> 0 | G11: =SUMIF(Details!$F$3:$F$102,D11,Details!$M$3:$M$102) -> 44 | H11: =SUMIF(Details!$G$3:$G$102,D11,Details!$N$3:$N$102) -> 0 | J11: =J10-7 -> 46188 | K11: {=SUMPRODUCT((Details!$A$3:$A$102>=J11)*(Details!$A$3:$A$102<J11+7)*(Details!$A$3:$A$102<>""))} -> 5 | L11: {=SUMPRODUCT((Details!$A$3:$A$102>=J11)*(Details!$A$3:$A$102<J11+7)*1,Details!$M$3:$M$102)} -> 9 | M11: {=SUMPRODUCT((Details!$B$3:$B$102>=J11)*(Details!$B$3:$B$102<J11+7)*(Details!$B$3:$B$102<>""))} -> 0 | N11: {=SUMPRODUCT((Details!$B$3:$B$102>=J11)*(Details!$B$3:$B$102<J11+7)*1,Details!$N$3:$N$102)} -> 0
A12: Tasks Blocked | B12: {=SUMPRODUCT((Details!$A$3:$A$102>=TODAY()-7)*(Details!$A$3:$A$102<=TODAY())*(Details!$K$3:$K$102="Blocked"))} -> 0 | D12: Ashish | E12: =COUNTIF(Details!$F$3:$F$102,D12) -> 3 | F12: =COUNTIF(Details!$G$3:$G$102,D12) -> 0 | G12: =SUMIF(Details!$F$3:$F$102,D12,Details!$M$3:$M$102) -> 0 | H12: =SUMIF(Details!$G$3:$G$102,D12,Details!$N$3:$N$102) -> 0 | J12: =J11-7 -> 46181 | K12: {=SUMPRODUCT((Details!$A$3:$A$102>=J12)*(Details!$A$3:$A$102<J12+7)*(Details!$A$3:$A$102<>""))} -> 3 | L12: {=SUMPRODUCT((Details!$A$3:$A$102>=J12)*(Details!$A$3:$A$102<J12+7)*1,Details!$M$3:$M$102)} -> 4 | M12: {=SUMPRODUCT((Details!$B$3:$B$102>=J12)*(Details!$B$3:$B$102<J12+7)*(Details!$B$3:$B$102<>""))} -> 1 | N12: {=SUMPRODUCT((Details!$B$3:$B$102>=J12)*(Details!$B$3:$B$102<J12+7)*1,Details!$N$3:$N$102)} -> 2
D13: TOTAL | E13: =SUM(E7:E12) -> 74 | F13: =SUM(F7:F12) -> 35 | G13: =SUM(G7:G12) -> 117.5 | H13: =SUM(H7:H12) -> 32.5 | J13: =J12-7 -> 46174 | K13: {=SUMPRODUCT((Details!$A$3:$A$102>=J13)*(Details!$A$3:$A$102<J13+7)*(Details!$A$3:$A$102<>""))} -> 5 | L13: {=SUMPRODUCT((Details!$A$3:$A$102>=J13)*(Details!$A$3:$A$102<J13+7)*1,Details!$M$3:$M$102)} -> 8 | M13: {=SUMPRODUCT((Details!$B$3:$B$102>=J13)*(Details!$B$3:$B$102<J13+7)*(Details!$B$3:$B$102<>""))} -> 0 | N13: {=SUMPRODUCT((Details!$B$3:$B$102>=J13)*(Details!$B$3:$B$102<J13+7)*1,Details!$N$3:$N$102)} -> 0
J14: =J13-7 -> 46167 | K14: {=SUMPRODUCT((Details!$A$3:$A$102>=J14)*(Details!$A$3:$A$102<J14+7)*(Details!$A$3:$A$102<>""))} -> 3 | L14: {=SUMPRODUCT((Details!$A$3:$A$102>=J14)*(Details!$A$3:$A$102<J14+7)*1,Details!$M$3:$M$102)} -> 2.5 | M14: {=SUMPRODUCT((Details!$B$3:$B$102>=J14)*(Details!$B$3:$B$102<J14+7)*(Details!$B$3:$B$102<>""))} -> 0 | N14: {=SUMPRODUCT((Details!$B$3:$B$102>=J14)*(Details!$B$3:$B$102<J14+7)*1,Details!$N$3:$N$102)} -> 0
A15: 📈 OVERALL STATISTICS | D15: 📆 MONTHLY STATISTICS
A16: Metric | B16: Value | D16: Month-Year | E16: Testing Tasks | F16: Testing Hours | G16: Orientation Tasks | H16: Orientation Hours | J16: 📊 STATUS BREAKDOWN BY RESOURCE
A17: Total Customers | B17: =COUNTA(Details!$C$3:$C$102)-COUNTIF(Details!$C$3:$C$102," ") -> 75 | D17: 45962 | E17: {=SUMPRODUCT((Details!$A$3:$A$102>=DATE(2025,11,1))*(Details!$A$3:$A$102<=DATE(2025,11,30))*(Details!$A$3:$A$102<>""))} -> 1 | F17: {=SUMPRODUCT((Details!$A$3:$A$102>=DATE(2025,11,1))*(Details!$A$3:$A$102<=DATE(2025,11,30))*1,Details!$M$3:$M$102)} -> 6 | G17: {=SUMPRODUCT((Details!$B$3:$B$102>=DATE(2025,11,1))*(Details!$B$3:$B$102<=DATE(2025,11,30))*(Details!$B$3:$B$102<>""))} -> 1 | H17: {=SUMPRODUCT((Details!$B$3:$B$102>=DATE(2025,11,1))*(Details!$B$3:$B$102<=DATE(2025,11,30))*1,Details!$N$3:$N$102)} -> 2 | J17: Resource | K17: Done | L17: Blocked | M17: Yet to Start | N17: In Progress
A18: Total Testing Hours | B18: =SUM(Details!$M$3:$M$102) -> 119.5 | D18: 45992 | E18: {=SUMPRODUCT((Details!$A$3:$A$102>=DATE(2025,12,1))*(Details!$A$3:$A$102<=DATE(2025,12,31))*(Details!$A$3:$A$102<>""))} -> 0 | F18: {=SUMPRODUCT((Details!$A$3:$A$102>=DATE(2025,12,1))*(Details!$A$3:$A$102<=DATE(2025,12,31))*1,Details!$M$3:$M$102)} -> 0 | G18: {=SUMPRODUCT((Details!$B$3:$B$102>=DATE(2025,12,1))*(Details!$B$3:$B$102<=DATE(2025,12,31))*(Details!$B$3:$B$102<>""))} -> 0 | H18: {=SUMPRODUCT((Details!$B$3:$B$102>=DATE(2025,12,1))*(Details!$B$3:$B$102<=DATE(2025,12,31))*1,Details!$N$3:$N$102)} -> 0 | J18: Jabali | K18: {=SUMPRODUCT((Details!$F$3:$F$102=J18)*(Details!$K$3:$K$102="Done"))} -> 4 | L18: {=SUMPRODUCT((Details!$F$3:$F$102=J18)*(Details!$K$3:$K$102="Blocked"))} -> 0 | M18: {=SUMPRODUCT((Details!$F$3:$F$102=J18)*(Details!$K$3:$K$102="Yet to Start"))} -> 0 | N18: {=SUMPRODUCT((Details!$F$3:$F$102=J18)*(Details!$K$3:$K$102="In Progress"))} -> 0
A19: Total Orientation Hours | B19: =SUM(Details!$N$3:$N$102) -> 48.5 | D19: 46023 | E19: {=SUMPRODUCT((Details!$A$3:$A$102>=DATE(2026,1,1))*(Details!$A$3:$A$102<=DATE(2026,1,31))*(Details!$A$3:$A$102<>""))} -> 0 | F19: {=SUMPRODUCT((Details!$A$3:$A$102>=DATE(2026,1,1))*(Details!$A$3:$A$102<=DATE(2026,1,31))*1,Details!$M$3:$M$102)} -> 0 | G19: {=SUMPRODUCT((Details!$B$3:$B$102>=DATE(2026,1,1))*(Details!$B$3:$B$102<=DATE(2026,1,31))*(Details!$B$3:$B$102<>""))} -> 0 | H19: {=SUMPRODUCT((Details!$B$3:$B$102>=DATE(2026,1,1))*(Details!$B$3:$B$102<=DATE(2026,1,31))*1,Details!$N$3:$N$102)} -> 0 | J19: DJ | K19: {=SUMPRODUCT((Details!$F$3:$F$102=J19)*(Details!$K$3:$K$102="Done"))} -> 4 | L19: {=SUMPRODUCT((Details!$F$3:$F$102=J19)*(Details!$K$3:$K$102="Blocked"))} -> 0 | M19: {=SUMPRODUCT((Details!$F$3:$F$102=J19)*(Details!$K$3:$K$102="Yet to Start"))} -> 0 | N19: {=SUMPRODUCT((Details!$F$3:$F$102=J19)*(Details!$K$3:$K$102="In Progress"))} -> 0
A20: Tasks Done | B20: =COUNTIF(Details!$K$3:$K$102,"Done") -> 69 | D20: 46054 | E20: {=SUMPRODUCT((Details!$A$3:$A$102>=DATE(2026,2,1))*(Details!$A$3:$A$102<=DATE(2026,2,28))*(Details!$A$3:$A$102<>""))} -> 4 | F20: {=SUMPRODUCT((Details!$A$3:$A$102>=DATE(2026,2,1))*(Details!$A$3:$A$102<=DATE(2026,2,28))*1,Details!$M$3:$M$102)} -> 5.5 | G20: {=SUMPRODUCT((Details!$B$3:$B$102>=DATE(2026,2,1))*(Details!$B$3:$B$102<=DATE(2026,2,28))*(Details!$B$3:$B$102<>""))} -> 0 | H20: {=SUMPRODUCT((Details!$B$3:$B$102>=DATE(2026,2,1))*(Details!$B$3:$B$102<=DATE(2026,2,28))*1,Details!$N$3:$N$102)} -> 0 | J20: Suraj | K20: {=SUMPRODUCT((Details!$F$3:$F$102=J20)*(Details!$K$3:$K$102="Done"))} -> 25 | L20: {=SUMPRODUCT((Details!$F$3:$F$102=J20)*(Details!$K$3:$K$102="Blocked"))} -> 0 | M20: {=SUMPRODUCT((Details!$F$3:$F$102=J20)*(Details!$K$3:$K$102="Yet to Start"))} -> 0 | N20: {=SUMPRODUCT((Details!$F$3:$F$102=J20)*(Details!$K$3:$K$102="In Progress"))} -> 0
A21: Tasks Blocked | B21: =COUNTIF(Details!$K$3:$K$102,"Blocked") -> 0 | D21: 46082 | E21: {=SUMPRODUCT((Details!$A$3:$A$102>=DATE(2026,3,1))*(Details!$A$3:$A$102<=DATE(2026,3,31))*(Details!$A$3:$A$102<>""))} -> 8 | F21: {=SUMPRODUCT((Details!$A$3:$A$102>=DATE(2026,3,1))*(Details!$A$3:$A$102<=DATE(2026,3,31))*1,Details!$M$3:$M$102)} -> 16 | G21: {=SUMPRODUCT((Details!$B$3:$B$102>=DATE(2026,3,1))*(Details!$B$3:$B$102<=DATE(2026,3,31))*(Details!$B$3:$B$102<>""))} -> 2 | H21: {=SUMPRODUCT((Details!$B$3:$B$102>=DATE(2026,3,1))*(Details!$B$3:$B$102<=DATE(2026,3,31))*1,Details!$N$3:$N$102)} -> 3 | J21: Pransshu | K21: {=SUMPRODUCT((Details!$F$3:$F$102=J21)*(Details!$K$3:$K$102="Done"))} -> 17 | L21: {=SUMPRODUCT((Details!$F$3:$F$102=J21)*(Details!$K$3:$K$102="Blocked"))} -> 0 | M21: {=SUMPRODUCT((Details!$F$3:$F$102=J21)*(Details!$K$3:$K$102="Yet to Start"))} -> 0 | N21: {=SUMPRODUCT((Details!$F$3:$F$102=J21)*(Details!$K$3:$K$102="In Progress"))} -> 0
A22: Tasks Yet to Start | B22: =COUNTIF(Details!$K$3:$K$102,"Yet to Start") -> 0 | D22: 46113 | E22: {=SUMPRODUCT((Details!$A$3:$A$102>=DATE(2026,4,1))*(Details!$A$3:$A$102<=DATE(2026,4,30))*(Details!$A$3:$A$102<>""))} -> 10 | F22: {=SUMPRODUCT((Details!$A$3:$A$102>=DATE(2026,4,1))*(Details!$A$3:$A$102<=DATE(2026,4,30))*1,Details!$M$3:$M$102)} -> 29.5 | G22: {=SUMPRODUCT((Details!$B$3:$B$102>=DATE(2026,4,1))*(Details!$B$3:$B$102<=DATE(2026,4,30))*(Details!$B$3:$B$102<>""))} -> 4 | H22: {=SUMPRODUCT((Details!$B$3:$B$102>=DATE(2026,4,1))*(Details!$B$3:$B$102<=DATE(2026,4,30))*1,Details!$N$3:$N$102)} -> 6 | J22: Sanjana | K22: {=SUMPRODUCT((Details!$F$3:$F$102=J22)*(Details!$K$3:$K$102="Done"))} -> 15 | L22: {=SUMPRODUCT((Details!$F$3:$F$102=J22)*(Details!$K$3:$K$102="Blocked"))} -> 0 | M22: {=SUMPRODUCT((Details!$F$3:$F$102=J22)*(Details!$K$3:$K$102="Yet to Start"))} -> 0 | N22: {=SUMPRODUCT((Details!$F$3:$F$102=J22)*(Details!$K$3:$K$102="In Progress"))} -> 0
A23: VPN Tasks | B23: =COUNTIF(Details!$E$3:$E$102,"VPN") -> 38 | D23: 46143 | E23: {=SUMPRODUCT((Details!$A$3:$A$102>=DATE(2026,5,1))*(Details!$A$3:$A$102<=DATE(2026,5,31))*(Details!$A$3:$A$102<>""))} -> 15 | F23: {=SUMPRODUCT((Details!$A$3:$A$102>=DATE(2026,5,1))*(Details!$A$3:$A$102<=DATE(2026,5,31))*1,Details!$M$3:$M$102)} -> 12 | G23: {=SUMPRODUCT((Details!$B$3:$B$102>=DATE(2026,5,1))*(Details!$B$3:$B$102<=DATE(2026,5,31))*(Details!$B$3:$B$102<>""))} -> 0 | H23: {=SUMPRODUCT((Details!$B$3:$B$102>=DATE(2026,5,1))*(Details!$B$3:$B$102<=DATE(2026,5,31))*1,Details!$N$3:$N$102)} -> 0 | J23: Ashish | K23: {=SUMPRODUCT((Details!$F$3:$F$102=J23)*(Details!$K$3:$K$102="Done"))} -> 3 | L23: {=SUMPRODUCT((Details!$F$3:$F$102=J23)*(Details!$K$3:$K$102="Blocked"))} -> 0 | M23: {=SUMPRODUCT((Details!$F$3:$F$102=J23)*(Details!$K$3:$K$102="Yet to Start"))} -> 0 | N23: {=SUMPRODUCT((Details!$F$3:$F$102=J23)*(Details!$K$3:$K$102="In Progress"))} -> 0
A24: Screen Share Tasks | B24: =COUNTIF(Details!$E$3:$E$102,"Screen Share") -> 30 | D24: 46174 | E24: {=SUMPRODUCT((Details!$A$3:$A$102>=DATE(2026,6,1))*(Details!$A$3:$A$102<=DATE(2026,6,30))*(Details!$A$3:$A$102<>""))} -> 21 | F24: {=SUMPRODUCT((Details!$A$3:$A$102>=DATE(2026,6,1))*(Details!$A$3:$A$102<=DATE(2026,6,30))*1,Details!$M$3:$M$102)} -> 26.5 | G24: {=SUMPRODUCT((Details!$B$3:$B$102>=DATE(2026,6,1))*(Details!$B$3:$B$102<=DATE(2026,6,30))*(Details!$B$3:$B$102<>""))} -> 2 | H24: {=SUMPRODUCT((Details!$B$3:$B$102>=DATE(2026,6,1))*(Details!$B$3:$B$102<=DATE(2026,6,30))*1,Details!$N$3:$N$102)} -> 2 | J24: TOTAL | K24: =SUM(K18:K23) -> 68 | L24: =SUM(L18:L23) -> 0 | M24: =SUM(M18:M23) -> 0 | N24: =SUM(N18:N23) -> 0
A27: 👥 PER RESOURCE PER WEEK STATISTICS (Last 4 Weeks) | H27: ⏱️ HOURS PER RESOURCE PER WEEK (Last 4 Weeks)
A28: Resource | B28: =TODAY()-WEEKDAY(TODAY(),2)+1 -> 46216 | C28: =B28-7 -> 46209 | D28: =C28-7 -> 46202 | E28: =D28-7 -> 46195 | F28: Total | H28: Resource | I28: =$B$28 -> 46216 | J28: =$C$28 -> 46209 | K28: =$D$28 -> 46202 | L28: =$E$28 -> 46195 | M28: Total Hrs
A29: Jabali | B29: {=SUMPRODUCT((Details!$A$3:$A$102>=$B$28)*(Details!$A$3:$A$102<$B$28+7)*(Details!$F$3:$F$102=A29))} -> 0 | C29: {=SUMPRODUCT((Details!$A$3:$A$102>=$C$28)*(Details!$A$3:$A$102<$C$28+7)*(Details!$F$3:$F$102=A29))} -> 0 | D29: {=SUMPRODUCT((Details!$A$3:$A$102>=$D$28)*(Details!$A$3:$A$102<$D$28+7)*(Details!$F$3:$F$102=A29))} -> 0 | E29: {=SUMPRODUCT((Details!$A$3:$A$102>=$E$28)*(Details!$A$3:$A$102<$E$28+7)*(Details!$F$3:$F$102=A29))} -> 0 | F29: =SUM(B29:E29) -> 0 | H29: Jabali | I29: =SUMIFS(Details!$M$3:$M$102,Details!$A$3:$A$102,">="&$B28,Details!$A$3:$A$102,"<"&$B28+7,Details!$F$3:$F$102,"Jabali") -> 0 | J29: =SUMIFS(Details!$M$3:$M$102,Details!$A$3:$A$102,">="&$C28,Details!$A$3:$A$102,"<"&$C28+7,Details!$F$3:$F$102,"Jabali") -> 0 | K29: =SUMIFS(Details!$M$3:$M$102,Details!$A$3:$A$102,">="&$D28,Details!$A$3:$A$102,"<"&$D28+7,Details!$F$3:$F$102,"Jabali") -> 0 | L29: =SUMIFS(Details!$M$3:$M$102,Details!$A$3:$A$102,">="&$E28,Details!$A$3:$A$102,"<"&$E28+7,Details!$F$3:$F$102,"Jabali") -> 0 | M29: =SUM(I29:L29) -> 0
A30: DJ | B30: {=SUMPRODUCT((Details!$A$3:$A$102>=$B$28)*(Details!$A$3:$A$102<$B$28+7)*(Details!$F$3:$F$102=A30))} -> 0 | C30: {=SUMPRODUCT((Details!$A$3:$A$102>=$C$28)*(Details!$A$3:$A$102<$C$28+7)*(Details!$F$3:$F$102=A30))} -> 0 | D30: {=SUMPRODUCT((Details!$A$3:$A$102>=$D$28)*(Details!$A$3:$A$102<$D$28+7)*(Details!$F$3:$F$102=A30))} -> 0 | E30: {=SUMPRODUCT((Details!$A$3:$A$102>=$E$28)*(Details!$A$3:$A$102<$E$28+7)*(Details!$F$3:$F$102=A30))} -> 0 | F30: =SUM(B30:E30) -> 0 | H30: DJ | I30: =SUMIFS(Details!$M$3:$M$102,Details!$A$3:$A$102,">="&$B28,Details!$A$3:$A$102,"<"&$B28+7,Details!$F$3:$F$102,"DJ") -> 0 | J30: =SUMIFS(Details!$M$3:$M$102,Details!$A$3:$A$102,">="&$C28,Details!$A$3:$A$102,"<"&$C28+7,Details!$F$3:$F$102,"DJ") -> 0 | K30: =SUMIFS(Details!$M$3:$M$102,Details!$A$3:$A$102,">="&$D28,Details!$A$3:$A$102,"<"&$D28+7,Details!$F$3:$F$102,"DJ") -> 0 | L30: =SUMIFS(Details!$M$3:$M$102,Details!$A$3:$A$102,">="&$E28,Details!$A$3:$A$102,"<"&$E28+7,Details!$F$3:$F$102,"DJ") -> 0 | M30: =SUM(I30:L30) -> 0
A31: Suraj | B31: {=SUMPRODUCT((Details!$A$3:$A$102>=$B$28)*(Details!$A$3:$A$102<$B$28+7)*(Details!$F$3:$F$102=A31))} -> 0 | C31: {=SUMPRODUCT((Details!$A$3:$A$102>=$C$28)*(Details!$A$3:$A$102<$C$28+7)*(Details!$F$3:$F$102=A31))} -> 3 | D31: {=SUMPRODUCT((Details!$A$3:$A$102>=$D$28)*(Details!$A$3:$A$102<$D$28+7)*(Details!$F$3:$F$102=A31))} -> 1 | E31: {=SUMPRODUCT((Details!$A$3:$A$102>=$E$28)*(Details!$A$3:$A$102<$E$28+7)*(Details!$F$3:$F$102=A31))} -> 5 | F31: =SUM(B31:E31) -> 9 | H31: Suraj | I31: =SUMIFS(Details!$M$3:$M$102,Details!$A$3:$A$102,">="&$B28,Details!$A$3:$A$102,"<"&$B28+7,Details!$F$3:$F$102,"Suraj") -> 0 | J31: =SUMIFS(Details!$M$3:$M$102,Details!$A$3:$A$102,">="&$C28,Details!$A$3:$A$102,"<"&$C28+7,Details!$F$3:$F$102,"Suraj") -> 4 | K31: =SUMIFS(Details!$M$3:$M$102,Details!$A$3:$A$102,">="&$D28,Details!$A$3:$A$102,"<"&$D28+7,Details!$F$3:$F$102,"Suraj") -> 1 | L31: =SUMIFS(Details!$M$3:$M$102,Details!$A$3:$A$102,">="&$E28,Details!$A$3:$A$102,"<"&$E28+7,Details!$F$3:$F$102,"Suraj") -> 3 | M31: =SUM(I31:L31) -> 8
A32: Pransshu | B32: {=SUMPRODUCT((Details!$A$3:$A$102>=$B$28)*(Details!$A$3:$A$102<$B$28+7)*(Details!$F$3:$F$102=A32))} -> 0 | C32: {=SUMPRODUCT((Details!$A$3:$A$102>=$C$28)*(Details!$A$3:$A$102<$C$28+7)*(Details!$F$3:$F$102=A32))} -> 0 | D32: {=SUMPRODUCT((Details!$A$3:$A$102>=$D$28)*(Details!$A$3:$A$102<$D$28+7)*(Details!$F$3:$F$102=A32))} -> 0 | E32: {=SUMPRODUCT((Details!$A$3:$A$102>=$E$28)*(Details!$A$3:$A$102<$E$28+7)*(Details!$F$3:$F$102=A32))} -> 2 | F32: =SUM(B32:E32) -> 2 | H32: Pransshu | I32: =SUMIFS(Details!$M$3:$M$102,Details!$A$3:$A$102,">="&$B28,Details!$A$3:$A$102,"<"&$B28+7,Details!$F$3:$F$102,"Pransshu") -> 0 | J32: =SUMIFS(Details!$M$3:$M$102,Details!$A$3:$A$102,">="&$C28,Details!$A$3:$A$102,"<"&$C28+7,Details!$F$3:$F$102,"Pransshu") -> 0 | K32: =SUMIFS(Details!$M$3:$M$102,Details!$A$3:$A$102,">="&$D28,Details!$A$3:$A$102,"<"&$D28+7,Details!$F$3:$F$102,"Pransshu") -> 0 | L32: =SUMIFS(Details!$M$3:$M$102,Details!$A$3:$A$102,">="&$E28,Details!$A$3:$A$102,"<"&$E28+7,Details!$F$3:$F$102,"Pransshu") -> 1.5 | M32: =SUM(I32:L32) -> 1.5
A33: Sanjana | B33: {=SUMPRODUCT((Details!$A$3:$A$102>=$B$28)*(Details!$A$3:$A$102<$B$28+7)*(Details!$F$3:$F$102=A33))} -> 0 | C33: {=SUMPRODUCT((Details!$A$3:$A$102>=$C$28)*(Details!$A$3:$A$102<$C$28+7)*(Details!$F$3:$F$102=A33))} -> 0 | D33: {=SUMPRODUCT((Details!$A$3:$A$102>=$D$28)*(Details!$A$3:$A$102<$D$28+7)*(Details!$F$3:$F$102=A33))} -> 0 | E33: {=SUMPRODUCT((Details!$A$3:$A$102>=$E$28)*(Details!$A$3:$A$102<$E$28+7)*(Details!$F$3:$F$102=A33))} -> 0 | F33: =SUM(B33:E33) -> 0 | H33: Sanjana | I33: =SUMIFS(Details!$M$3:$M$102,Details!$A$3:$A$102,">="&$B28,Details!$A$3:$A$102,"<"&$B28+7,Details!$F$3:$F$102,"Sanjana") -> 0 | J33: =SUMIFS(Details!$M$3:$M$102,Details!$A$3:$A$102,">="&$C28,Details!$A$3:$A$102,"<"&$C28+7,Details!$F$3:$F$102,"Sanjana") -> 0 | K33: =SUMIFS(Details!$M$3:$M$102,Details!$A$3:$A$102,">="&$D28,Details!$A$3:$A$102,"<"&$D28+7,Details!$F$3:$F$102,"Sanjana") -> 0 | L33: =SUMIFS(Details!$M$3:$M$102,Details!$A$3:$A$102,">="&$E28,Details!$A$3:$A$102,"<"&$E28+7,Details!$F$3:$F$102,"Sanjana") -> 0 | M33: =SUM(I33:L33) -> 0
A34: Ashish | B34: {=SUMPRODUCT((Details!$A$3:$A$102>=$B$28)*(Details!$A$3:$A$102<$B$28+7)*(Details!$F$3:$F$102=A34))} -> 0 | C34: {=SUMPRODUCT((Details!$A$3:$A$102>=$C$28)*(Details!$A$3:$A$102<$C$28+7)*(Details!$F$3:$F$102=A34))} -> 0 | D34: {=SUMPRODUCT((Details!$A$3:$A$102>=$D$28)*(Details!$A$3:$A$102<$D$28+7)*(Details!$F$3:$F$102=A34))} -> 0 | E34: {=SUMPRODUCT((Details!$A$3:$A$102>=$E$28)*(Details!$A$3:$A$102<$E$28+7)*(Details!$F$3:$F$102=A34))} -> 0 | F34: =SUM(B34:E34) -> 0 | H34: Ashish | I34: =SUMIFS(Details!$M$3:$M$102,Details!$A$3:$A$102,">="&$B28,Details!$A$3:$A$102,"<"&$B28+7,Details!$F$3:$F$102,"Ashish") -> 0 | J34: =SUMIFS(Details!$M$3:$M$102,Details!$A$3:$A$102,">="&$C28,Details!$A$3:$A$102,"<"&$C28+7,Details!$F$3:$F$102,"Ashish") -> 0 | K34: =SUMIFS(Details!$M$3:$M$102,Details!$A$3:$A$102,">="&$D28,Details!$A$3:$A$102,"<"&$D28+7,Details!$F$3:$F$102,"Ashish") -> 0 | L34: =SUMIFS(Details!$M$3:$M$102,Details!$A$3:$A$102,">="&$E28,Details!$A$3:$A$102,"<"&$E28+7,Details!$F$3:$F$102,"Ashish") -> 0 | M34: =SUM(I34:L34) -> 0
A35: TOTAL | B35: =SUM(B29:B34) -> 0 | C35: =SUM(C29:C34) -> 3 | D35: =SUM(D29:D34) -> 1 | E35: =SUM(E29:E34) -> 7 | F35: =SUM(F29:F34) -> 11 | H35: TOTAL | I35: =SUM(I29:I34) -> 0 | J35: =SUM(J29:J34) -> 4 | K35: =SUM(K29:K34) -> 1 | L35: =SUM(L29:L34) -> 4.5 | M35: =SUM(I35:L35) -> 9.5
A38: 🔌 TYPE BREAKDOWN BY RESOURCE | F38: 📅 CURRENT MONTH STATISTICS
A39: Resource | B39: VPN Tasks | C39: Screen Share Tasks | D39: Total | F39: Metric | G39: Value
A40: Jabali | B40: {=SUMPRODUCT((Details!$F$3:$F$102=A40)*(Details!$E$3:$E$102="VPN"))} -> 2 | C40: {=SUMPRODUCT((Details!$F$3:$F$102=A40)*(Details!$E$3:$E$102="Screen Share"))} -> 1 | D40: =B40+C40 -> 3 | F40: Current Month | G40: =TEXT(TODAY(),"MMMM YYYY") -> July 2026
A41: DJ | B41: {=SUMPRODUCT((Details!$F$3:$F$102=A41)*(Details!$E$3:$E$102="VPN"))} -> 0 | C41: {=SUMPRODUCT((Details!$F$3:$F$102=A41)*(Details!$E$3:$E$102="Screen Share"))} -> 2 | D41: =B41+C41 -> 2 | F41: Testing Tasks | G41: =COUNTIFS(Details!$A$3:$A$102,">="&DATE(YEAR(TODAY()),MONTH(TODAY()),1),Details!$A$3:$A$102,"<"&DATE(YEAR(TODAY()),MONTH(TODAY())+1,1)) -> 3
A42: Suraj | B42: {=SUMPRODUCT((Details!$F$3:$F$102=A42)*(Details!$E$3:$E$102="VPN"))} -> 18 | C42: {=SUMPRODUCT((Details!$F$3:$F$102=A42)*(Details!$E$3:$E$102="Screen Share"))} -> 9 | D42: =B42+C42 -> 27 | F42: Orientation Tasks | G42: =COUNTIFS(Details!$B$3:$B$102,">="&DATE(YEAR(TODAY()),MONTH(TODAY()),1),Details!$B$3:$B$102,"<"&DATE(YEAR(TODAY()),MONTH(TODAY())+1,1)) -> 3
A43: Pransshu | B43: {=SUMPRODUCT((Details!$F$3:$F$102=A43)*(Details!$E$3:$E$102="VPN"))} -> 11 | C43: {=SUMPRODUCT((Details!$F$3:$F$102=A43)*(Details!$E$3:$E$102="Screen Share"))} -> 9 | D43: =B43+C43 -> 20 | F43: Testing Hours | G43: =SUMIFS(Details!$M$3:$M$102,Details!$A$3:$A$102,">="&DATE(YEAR(TODAY()),MONTH(TODAY()),1),Details!$A$3:$A$102,"<"&DATE(YEAR(TODAY()),MONTH(TODAY())+1,1)) -> 4
A44: Sanjana | B44: {=SUMPRODUCT((Details!$F$3:$F$102=A44)*(Details!$E$3:$E$102="VPN"))} -> 7 | C44: {=SUMPRODUCT((Details!$F$3:$F$102=A44)*(Details!$E$3:$E$102="Screen Share"))} -> 8 | D44: =B44+C44 -> 15 | F44: Orientation Hours | G44: =SUMIFS(Details!$N$3:$N$102,Details!$B$3:$B$102,">="&DATE(YEAR(TODAY()),MONTH(TODAY()),1),Details!$B$3:$B$102,"<"&DATE(YEAR(TODAY()),MONTH(TODAY())+1,1)) -> 2
A45: Ashish | B45: {=SUMPRODUCT((Details!$F$3:$F$102=A45)*(Details!$E$3:$E$102="VPN"))} -> 0 | C45: {=SUMPRODUCT((Details!$F$3:$F$102=A45)*(Details!$E$3:$E$102="Screen Share"))} -> 0 | D45: =B45+C45 -> 0 | F45: Tasks Completed | G45: =COUNTIFS(Details!$A$3:$A$102,">="&DATE(YEAR(TODAY()),MONTH(TODAY()),1),Details!$A$3:$A$102,"<"&DATE(YEAR(TODAY()),MONTH(TODAY())+1,1),Details!$K$3:$K$102,"Done") -> 3
A46: TOTAL | B46: =SUM(B40:B45) -> 38 | C46: =SUM(C40:C45) -> 29 | D46: =SUM(D40:D45) -> 67

Sheet Charts
